{
 "cells": [
  {
   "cell_type": "code",
   "execution_count": 35,
   "metadata": {},
   "outputs": [
    {
     "name": "stderr",
     "output_type": "stream",
     "text": [
      "/var/folders/rf/dqdwsk6s06ngm9b4j17fkb2r0000gn/T/ipykernel_95754/3291834190.py:6: DtypeWarning: Columns (28,29,30,31,32,35,41,42,43,44,45,46,50) have mixed types. Specify dtype option on import or set low_memory=False.\n",
      "  liste_med_ban = pd.read_csv('liste_med_ban.csv')\n"
     ]
    }
   ],
   "source": [
    "import pandas as pd\n",
    "import numpy as np\n",
    "import requests\n",
    "import math\n",
    "\n",
    "liste_med_ban = pd.read_csv('liste_med_ban.csv')"
   ]
  },
  {
   "cell_type": "code",
   "execution_count": 28,
   "metadata": {},
   "outputs": [],
   "source": [
    "def cp_et_nom(cp,nom):\n",
    "    if isinstance(cp,int) and isinstance(nom,str):\n",
    "        return (str(cp)+' '+nom)\n",
    "    else:\n",
    "        return np.nan"
   ]
  },
  {
   "cell_type": "code",
   "execution_count": 29,
   "metadata": {},
   "outputs": [
    {
     "data": {
      "text/plain": [
       "'94456 Limeil-Brévannes'"
      ]
     },
     "execution_count": 29,
     "metadata": {},
     "output_type": "execute_result"
    }
   ],
   "source": [
    "liste_med_ban['cp_ville'] = liste_med_ban.apply(lambda x: cp_et_nom(x['codepostalcoordstructure'],x['libellécommunecoordstructure']),axis=1)\n",
    "liste_med_ban['cp_ville'].iloc[73370]"
   ]
  },
  {
   "cell_type": "code",
   "execution_count": 30,
   "metadata": {},
   "outputs": [],
   "source": [
    "API_URL = \"https://api-adresse.data.gouv.fr/{}/\"\n",
    "\n",
    "def req_to(endpoint: str, params: dict | None = None, files: dict | None = None) -> dict:\n",
    "    url = API_URL.format(endpoint)\n",
    "\n",
    "    if not files:\n",
    "        response = requests.get(url, params=params)\n",
    "\n",
    "    else:\n",
    "        response = requests.post(url, files=files, data=params)\n",
    "\n",
    "    if response.status_code == 200:\n",
    "        data = response.json()\n",
    "        return data\n",
    "    else:\n",
    "        raise Exception(f\"Request failed with code : {response.status_code}\")\n",
    "\n",
    "\n",
    "def get_geocode(**kwargs) -> dict:\n",
    "    if not 'q' in kwargs:\n",
    "        raise ValueError('Il manque un argument obligatoire : q')\n",
    "    \n",
    "    return req_to(\"search\", kwargs)\n",
    "\n",
    "\n",
    "def get_reverse(**kwargs) -> dict:\n",
    "    if not('lat' in kwargs and 'lon' in kwargs):\n",
    "        raise ValueError('Il manque des arguments obligatoires : lat et lon')\n",
    "    \n",
    "    return req_to(\"reverse\", kwargs)\n",
    "\n",
    "\n",
    "def get_geocode_csv(file_path: str, **kwargs) -> dict:\n",
    "    with open(file_path, 'rb') as file:\n",
    "        files = {'data': file}\n",
    "        response = req_to(\"search/csv\", kwargs, files) \n",
    "    \n",
    "    return response\n",
    "\n",
    "\n",
    "def get_reverse_csv(file_path: str) -> dict:\n",
    "    with open(file_path, 'rb') as file:\n",
    "        files = {'data': file}\n",
    "        response = req_to(\"reverse/csv\", files=files) \n",
    "\n",
    "    return response"
   ]
  },
  {
   "cell_type": "code",
   "execution_count": 31,
   "metadata": {},
   "outputs": [
    {
     "name": "stdout",
     "output_type": "stream",
     "text": [
      "52, rue jean jaures, 97110 Pointe-à-Pitre\n",
      "{'type': 'FeatureCollection', 'version': 'draft', 'features': [{'type': 'Feature', 'geometry': {'type': 'Point', 'coordinates': [-61.536772, 16.23989]}, 'properties': {'label': '52 Rue Jean Jaures 97110 Pointe-à-Pitre', 'score': 0.9688018181818181, 'housenumber': '52', 'id': '97120_0496_00052', 'banId': '3565ae2f-5cbf-4aab-8543-7a3fda9b9059', 'name': '52 Rue Jean Jaures', 'postcode': '97110', 'citycode': '97120', 'x': 656379.35, 'y': 1796029.48, 'city': 'Pointe-à-Pitre', 'context': '971, Guadeloupe', 'type': 'housenumber', 'importance': 0.65682, 'street': 'Rue Jean Jaures'}}], 'attribution': 'BAN', 'licence': 'ETALAB-2.0', 'query': '52, rue jean jaures, 97110 Pointe-à-Pitre', 'limit': 5}\n",
      "<class 'list'> [-61.536772, 16.23989]\n"
     ]
    }
   ],
   "source": [
    "numero=str(int(liste_med_ban['numérovoiecoordstructure'].iloc[0]))\n",
    "voie = liste_med_ban['Voie'].iloc[0]\n",
    "cp_ville=liste_med_ban['cp_ville'].iloc[0]\n",
    "adresse = numero+', '+voie+', '+cp_ville\n",
    "print(adresse)\n",
    "\n",
    "# Requête simple directe:\n",
    "res = get_geocode(q = adresse)\n",
    "print(res)\n",
    "print(type(res['properties']),res['properties'][0]['x'])"
   ]
  },
  {
   "cell_type": "code",
   "execution_count": 33,
   "metadata": {},
   "outputs": [
    {
     "name": "stdout",
     "output_type": "stream",
     "text": [
      "Unexpected exception formatting exception. Falling back to standard exception\n"
     ]
    },
    {
     "name": "stderr",
     "output_type": "stream",
     "text": [
      "Traceback (most recent call last):\n",
      "  File \"/Users/julie/miniconda3/lib/python3.11/site-packages/urllib3/connection.py\", line 174, in _new_conn\n",
      "    However, the hostname with trailing dot is critical to DNS resolution; doing a\n",
      "               ^^^^^^^^^^^^^^^^^^^^^^^^^^^^^^^^^^^^^^^^^^^^^^^^^^^^^^^^^^^^^^^^^^^\n",
      "  File \"/Users/julie/miniconda3/lib/python3.11/site-packages/urllib3/util/connection.py\", line 95, in create_connection\n",
      "    ) -> None:\n",
      "            ^^^\n",
      "  File \"/Users/julie/miniconda3/lib/python3.11/site-packages/urllib3/util/connection.py\", line 85, in create_connection\n",
      "    raise err\n",
      "OSError: [Errno 51] Network is unreachable\n",
      "\n",
      "During handling of the above exception, another exception occurred:\n",
      "\n",
      "Traceback (most recent call last):\n",
      "  File \"/Users/julie/miniconda3/lib/python3.11/site-packages/urllib3/connectionpool.py\", line 714, in urlopen\n",
      "    retries = Retry.from_int(retries, redirect=redirect, default=self.retries)\n",
      "                       ^^^^^^^^^^^^^^^^^^^^^^^^^^^^^^^^^^^^^^^^^^^^^^^^^^^^^^^\n",
      "  File \"/Users/julie/miniconda3/lib/python3.11/site-packages/urllib3/connectionpool.py\", line 403, in _make_request\n",
      "  File \"/Users/julie/miniconda3/lib/python3.11/site-packages/urllib3/connectionpool.py\", line 1053, in _validate_conn\n",
      "    self.num_connections,\n",
      "    ^^^^^^^^^^^^^^\n",
      "  File \"/Users/julie/miniconda3/lib/python3.11/site-packages/urllib3/connection.py\", line 363, in connect\n",
      "    # `request` method's signature intentionally violates LSP.\n",
      "                           ^^^^^^^^^^^^^^^^\n",
      "  File \"/Users/julie/miniconda3/lib/python3.11/site-packages/urllib3/connection.py\", line 186, in _new_conn\n",
      "    Setter for the `host` property.\n",
      "        ^^^^^^^^^^^^^^^^^^^^^^^^^^^\n",
      "urllib3.exceptions.NewConnectionError: <urllib3.connection.HTTPSConnection object at 0x1223c1490>: Failed to establish a new connection: [Errno 51] Network is unreachable\n",
      "\n",
      "During handling of the above exception, another exception occurred:\n",
      "\n",
      "Traceback (most recent call last):\n",
      "  File \"/Users/julie/miniconda3/lib/python3.11/site-packages/requests/adapters.py\", line 486, in send\n",
      "    )\n",
      "      \n",
      "  File \"/Users/julie/miniconda3/lib/python3.11/site-packages/urllib3/connectionpool.py\", line 798, in urlopen\n",
      "    response_conn=response_conn,\n",
      "          ^^^^^^^^^^^^^^^^^^^^^^\n",
      "  File \"/Users/julie/miniconda3/lib/python3.11/site-packages/urllib3/util/retry.py\", line 592, in increment\n",
      "urllib3.exceptions.MaxRetryError: HTTPSConnectionPool(host='api-adresse.data.gouv.fr', port=443): Max retries exceeded with url: /search/?q=157%2C+rue+de+la+pte+de+trivaux%2C+92140+Clamart (Caused by NewConnectionError('<urllib3.connection.HTTPSConnection object at 0x1223c1490>: Failed to establish a new connection: [Errno 51] Network is unreachable'))\n",
      "\n",
      "During handling of the above exception, another exception occurred:\n",
      "\n",
      "Traceback (most recent call last):\n",
      "  File \"/Users/julie/miniconda3/lib/python3.11/site-packages/IPython/core/interactiveshell.py\", line 3526, in run_code\n",
      "    exec(code_obj, self.user_global_ns, self.user_ns)\n",
      "  File \"/var/folders/rf/dqdwsk6s06ngm9b4j17fkb2r0000gn/T/ipykernel_95754/3440838157.py\", line 17, in <module>\n",
      "    liste_med_ban['longitude API'] = liste_med_ban['adresse'].apply(recup_long)\n",
      "                                     ^^^^^^^^^^^^^^^^^^^^^^^^^^^^^^^^^^^^^^^^^^\n",
      "  File \"/Users/julie/miniconda3/lib/python3.11/site-packages/pandas/core/series.py\", line 4924, in apply\n",
      "    ).apply()\n",
      "      ^^^^^^^\n",
      "  File \"/Users/julie/miniconda3/lib/python3.11/site-packages/pandas/core/apply.py\", line 1427, in apply\n",
      "    return self.apply_standard()\n",
      "           ^^^^^^^^^^^^^^^^^^^^^\n",
      "  File \"/Users/julie/miniconda3/lib/python3.11/site-packages/pandas/core/apply.py\", line 1507, in apply_standard\n",
      "    mapped = obj._map_values(\n",
      "             ^^^^^^^^^^^^^^^^\n",
      "  File \"/Users/julie/miniconda3/lib/python3.11/site-packages/pandas/core/base.py\", line 921, in _map_values\n",
      "    return algorithms.map_array(arr, mapper, na_action=na_action, convert=convert)\n",
      "           ^^^^^^^^^^^^^^^^^^^^^^^^^^^^^^^^^^^^^^^^^^^^^^^^^^^^^^^^^^^^^^^^^^^^^^^\n",
      "  File \"/Users/julie/miniconda3/lib/python3.11/site-packages/pandas/core/algorithms.py\", line 1743, in map_array\n",
      "    return lib.map_infer(values, mapper, convert=convert)\n",
      "           ^^^^^^^^^^^^^^^^^^^^^^^^^^^^^^^^^^^^^^^^^^^^^^\n",
      "  File \"lib.pyx\", line 2972, in pandas._libs.lib.map_infer\n",
      "  File \"/var/folders/rf/dqdwsk6s06ngm9b4j17fkb2r0000gn/T/ipykernel_95754/3440838157.py\", line 10, in recup_long\n",
      "    return(get_geocode(q=adr)['features'][0]['geometry']['coordinates'][0])\n",
      "           ^^^^^^^^^^^^^^^^^^\n",
      "  File \"/var/folders/rf/dqdwsk6s06ngm9b4j17fkb2r0000gn/T/ipykernel_95754/4204138459.py\", line 23, in get_geocode\n",
      "    return req_to(\"search\", kwargs)\n",
      "           ^^^^^^^^^^^^^^^^^^^^^^^^\n",
      "  File \"/var/folders/rf/dqdwsk6s06ngm9b4j17fkb2r0000gn/T/ipykernel_95754/4204138459.py\", line 7, in req_to\n",
      "    response = requests.get(url, params=params)\n",
      "               ^^^^^^^^^^^^^^^^^^^^^^^^^^^^^^^^\n",
      "  File \"/Users/julie/miniconda3/lib/python3.11/site-packages/requests/api.py\", line 73, in get\n",
      "    return request(\"get\", url, params=params, **kwargs)\n",
      "           ^^^^^^^^^^^^^^^^^^^^^^^^^^^^^^^^^^^^^^^^^^^^\n",
      "  File \"/Users/julie/miniconda3/lib/python3.11/site-packages/requests/api.py\", line 59, in request\n",
      "    return session.request(method=method, url=url, **kwargs)\n",
      "           ^^^^^^^^^^^^^^^^^^^^^^^^^^^^^^^^^^^^^^^^^^^^^^^^^\n",
      "  File \"/Users/julie/miniconda3/lib/python3.11/site-packages/requests/sessions.py\", line 589, in request\n",
      "    resp = self.send(prep, **send_kwargs)\n",
      "           ^^^^^^^^^^^^^^^^^^^^^^^^^^^^^^\n",
      "  File \"/Users/julie/miniconda3/lib/python3.11/site-packages/requests/sessions.py\", line 703, in send\n",
      "    r = adapter.send(request, **kwargs)\n",
      "        ^^^^^^^^^^^^^^^^^^^^^^^^^^^^^^^\n",
      "  File \"/Users/julie/miniconda3/lib/python3.11/site-packages/requests/adapters.py\", line 519, in send\n",
      "    proxy = prepend_scheme_if_needed(proxy, \"http\")\n",
      "    ^^^^^^^^^^^^^^^^^^^^^^^^^^^^^^^^^^^^^^^^^\n",
      "requests.exceptions.ConnectionError: HTTPSConnectionPool(host='api-adresse.data.gouv.fr', port=443): Max retries exceeded with url: /search/?q=157%2C+rue+de+la+pte+de+trivaux%2C+92140+Clamart (Caused by NewConnectionError('<urllib3.connection.HTTPSConnection object at 0x1223c1490>: Failed to establish a new connection: [Errno 51] Network is unreachable'))\n",
      "\n",
      "During handling of the above exception, another exception occurred:\n",
      "\n",
      "Traceback (most recent call last):\n",
      "  File \"/Users/julie/miniconda3/lib/python3.11/site-packages/IPython/core/interactiveshell.py\", line 2120, in showtraceback\n",
      "    stb = self.InteractiveTB.structured_traceback(\n",
      "          ^^^^^^^^^^^^^^^^^^^^^^^^^^^^^^^^^^^^^^^^\n",
      "  File \"/Users/julie/miniconda3/lib/python3.11/site-packages/IPython/core/ultratb.py\", line 1435, in structured_traceback\n",
      "    return FormattedTB.structured_traceback(\n",
      "           ^^^^^^^^^^^^^^^^^^^^^^^^^^^^^^^^^\n",
      "  File \"/Users/julie/miniconda3/lib/python3.11/site-packages/IPython/core/ultratb.py\", line 1326, in structured_traceback\n",
      "    return VerboseTB.structured_traceback(\n",
      "           ^^^^^^^^^^^^^^^^^^^^^^^^^^^^^^^\n",
      "  File \"/Users/julie/miniconda3/lib/python3.11/site-packages/IPython/core/ultratb.py\", line 1173, in structured_traceback\n",
      "    formatted_exception = self.format_exception_as_a_whole(etype, evalue, etb, number_of_lines_of_context,\n",
      "                          ^^^^^^^^^^^^^^^^^^^^^^^^^^^^^^^^^^^^^^^^^^^^^^^^^^^^^^^^^^^^^^^^^^^^^^^^^^^^^^^^\n",
      "  File \"/Users/julie/miniconda3/lib/python3.11/site-packages/IPython/core/ultratb.py\", line 1063, in format_exception_as_a_whole\n",
      "    self.get_records(etb, number_of_lines_of_context, tb_offset) if etb else []\n",
      "    ^^^^^^^^^^^^^^^^^^^^^^^^^^^^^^^^^^^^^^^^^^^^^^^^^^^^^^^^^^^^\n",
      "  File \"/Users/julie/miniconda3/lib/python3.11/site-packages/IPython/core/ultratb.py\", line 1115, in get_records\n",
      "    style = stack_data.style_with_executing_node(style, self._tb_highlight)\n",
      "            ^^^^^^^^^^^^^^^^^^^^^^^^^^^^^^^^^^^^^^^^^^^^^^^^^^^^^^^^^^^^^^^\n",
      "  File \"/Users/julie/miniconda3/lib/python3.11/site-packages/stack_data/core.py\", line 455, in style_with_executing_node\n",
      "    class NewStyle(style):\n",
      "  File \"/Users/julie/miniconda3/lib/python3.11/site-packages/pygments/style.py\", line 91, in __new__\n",
      "    ndef[4] = colorformat(styledef[3:])\n",
      "              ^^^^^^^^^^^^^^^^^^^^^^^^^\n",
      "  File \"/Users/julie/miniconda3/lib/python3.11/site-packages/pygments/style.py\", line 58, in colorformat\n",
      "    assert False, \"wrong color format %r\" % text\n",
      "AssertionError: wrong color format 'ansiyellow'\n"
     ]
    }
   ],
   "source": [
    "def transfo_adresse(CodePostal,NumeroVoie,NomVoie):\n",
    "    num = (int(NumeroVoie))\n",
    "    return (str(num)+', '+str(NomVoie)+', '+str(CodePostal))\n",
    "\n",
    "liste_med_ban['adresse'] = liste_med_ban.apply(lambda x: transfo_adresse(x['cp_ville'],x['numérovoiecoordstructure'],x['Voie']),axis=1)\n",
    "\n",
    "def recup_long(adr):\n",
    "    if isinstance(adr,str):\n",
    "        try:\n",
    "            return(get_geocode(q=adr)['features'][0]['geometry']['coordinates'][0])\n",
    "        except (IndexError, KeyError, TypeError):\n",
    "            print(adr)\n",
    "            return None\n",
    "    else :\n",
    "        return (np.nan)\n",
    "\n",
    "liste_med_ban['longitude API'] = liste_med_ban['adresse'].apply(recup_long)\n",
    "#liste_med_ban['latitude API'] = get_geocode(q = liste_med_ban['adresse'])['features'][0]['geometry']['coordinates'][1]\n",
    "\n",
    "#liste_med_ban['adresse','longitude API','latitude API']"
   ]
  },
  {
   "cell_type": "code",
   "execution_count": 36,
   "metadata": {},
   "outputs": [
    {
     "name": "stdout",
     "output_type": "stream",
     "text": [
      "La distance entre Paris et Los Angeles est d'environ 9085.51 km.\n"
     ]
    }
   ],
   "source": [
    "def distance_long_lat(lat1, lon1, lat2, lon2):\n",
    "    # Rayon de la Terre en km\n",
    "    R = 6371.0\n",
    "    \n",
    "    # Conversion des degrés en radians\n",
    "    lat1_rad = math.radians(lat1)\n",
    "    lon1_rad = math.radians(lon1)\n",
    "    lat2_rad = math.radians(lat2)\n",
    "    lon2_rad = math.radians(lon2)\n",
    "    \n",
    "    # Calcul des différences\n",
    "    delta_lat = lat2_rad - lat1_rad\n",
    "    delta_lon = lon2_rad - lon1_rad\n",
    "    \n",
    "    # Formule de Haversine\n",
    "    a = math.sin(delta_lat / 2)**2 + math.cos(lat1_rad) * math.cos(lat2_rad) * math.sin(delta_lon / 2)**2\n",
    "    c = 2 * math.asin(math.sqrt(a))\n",
    "    \n",
    "    # Distance\n",
    "    distance = R * c\n",
    "    \n",
    "    return distance\n",
    "\n",
    "# Exemple d'utilisation\n",
    "lat1, lon1 = 48.8566, 2.3522  # Paris\n",
    "lat2, lon2 = 34.0522, -118.2437  # Los Angeles\n",
    "\n",
    "distance = distance_long_lat(lat1, lon1, lat2, lon2)\n",
    "print(f\"La distance entre Paris et Los Angeles est d'environ {distance:.2f} km.\")\n"
   ]
  }
 ],
 "metadata": {
  "kernelspec": {
   "display_name": "base",
   "language": "python",
   "name": "python3"
  },
  "language_info": {
   "codemirror_mode": {
    "name": "ipython",
    "version": 3
   },
   "file_extension": ".py",
   "mimetype": "text/x-python",
   "name": "python",
   "nbconvert_exporter": "python",
   "pygments_lexer": "ipython3",
   "version": "3.11.4"
  }
 },
 "nbformat": 4,
 "nbformat_minor": 2
}
